Failure # 1 (occurred at 2025-05-22_20-51-05)
[36mray::ImplicitFunc.train()[39m (pid=59200, ip=127.0.0.1, actor_id=f7aeff52c8c8947a897ce51f02000000, repr=objective)
           ^^^^^^^^^^^^^^^^^^^^^^^^^^^^^^^^^^^^
           ^^^^^^^^^^^^^^^^^^^^^^^^^^^^^^^
  File "/opt/homebrew/Caskroom/miniconda/base/envs/py311ray/lib/python3.11/site-packages/ray/tune/trainable/trainable.py", line 330, in train
    raise skipped from exception_cause(skipped)
  File "/opt/homebrew/Caskroom/miniconda/base/envs/py311ray/lib/python3.11/site-packages/ray/air/_internal/util.py", line 107, in run
    self._ret = self._target(*self._args, **self._kwargs)
                ^^^^^^^^^^^^^^^^^^^^^^^^^^^^^^^^^^^^^^^^^
  File "/opt/homebrew/Caskroom/miniconda/base/envs/py311ray/lib/python3.11/site-packages/ray/tune/trainable/function_trainable.py", line 45, in <lambda>
    training_func=lambda: self._trainable_func(self.config),
                          ^^^^^^^^^^^^^^^^^^^^^^^^^^^^^^^^^
           ^^^^^^^^^^^^^^^^^^^^^^^^^^^^^^^
  File "/opt/homebrew/Caskroom/miniconda/base/envs/py311ray/lib/python3.11/site-packages/ray/tune/trainable/function_trainable.py", line 261, in _trainable_func
    output = fn()
             ^^^^
  File "/Users/mikeedwards/Library/Mobile Documents/com~apple~CloudDocs/pMike/Unity/price/run_optuna.py", line 55, in objective
    tune.report(loss=loss)                        # every trial must report!
    ^^^^^^^^^^^^^^^^^^^^^^
  File "/opt/homebrew/Caskroom/miniconda/base/envs/py311ray/lib/python3.11/site-packages/ray/train/_internal/session.py", line 663, in wrapper
    return fn(*args, **kwargs)
           ^^^^^^^^^^^^^^^^^^^
TypeError: report() got an unexpected keyword argument 'loss'
Failure # 2 (occurred at 2025-05-22_20-51-44)
[36mray::ImplicitFunc.train()[39m (pid=59377, ip=127.0.0.1, actor_id=4a40820ce04fd5ba555ab16602000000, repr=objective)
           ^^^^^^^^^^^^^^^^^^^^^^^^^^^^^^^^^^^^
           ^^^^^^^^^^^^^^^^^^^^^^^^^^^^^^^
  File "/opt/homebrew/Caskroom/miniconda/base/envs/py311ray/lib/python3.11/site-packages/ray/tune/trainable/trainable.py", line 330, in train
    raise skipped from exception_cause(skipped)
  File "/opt/homebrew/Caskroom/miniconda/base/envs/py311ray/lib/python3.11/site-packages/ray/air/_internal/util.py", line 107, in run
    self._ret = self._target(*self._args, **self._kwargs)
                ^^^^^^^^^^^^^^^^^^^^^^^^^^^^^^^^^^^^^^^^^
  File "/opt/homebrew/Caskroom/miniconda/base/envs/py311ray/lib/python3.11/site-packages/ray/tune/trainable/function_trainable.py", line 45, in <lambda>
    training_func=lambda: self._trainable_func(self.config),
                          ^^^^^^^^^^^^^^^^^^^^^^^^^^^^^^^^^
           ^^^^^^^^^^^^^^^^^^^^^^^^^^^^^^^
  File "/opt/homebrew/Caskroom/miniconda/base/envs/py311ray/lib/python3.11/site-packages/ray/tune/trainable/function_trainable.py", line 261, in _trainable_func
    output = fn()
             ^^^^
  File "/Users/mikeedwards/Library/Mobile Documents/com~apple~CloudDocs/pMike/Unity/price/run_optuna.py", line 55, in objective
    tune.report(loss=loss)                        # every trial must report!
    ^^^^^^^^^^^^^^^^^^^^^^
  File "/opt/homebrew/Caskroom/miniconda/base/envs/py311ray/lib/python3.11/site-packages/ray/train/_internal/session.py", line 663, in wrapper
    return fn(*args, **kwargs)
           ^^^^^^^^^^^^^^^^^^^
TypeError: report() got an unexpected keyword argument 'loss'
Failure # 3 (occurred at 2025-05-22_20-52-24)
[36mray::ImplicitFunc.train()[39m (pid=59551, ip=127.0.0.1, actor_id=56c6edae30286f9e9544b6ed02000000, repr=objective)
           ^^^^^^^^^^^^^^^^^^^^^^^^^^^^^^^^^^^^
           ^^^^^^^^^^^^^^^^^^^^^^^^^^^^^^^
  File "/opt/homebrew/Caskroom/miniconda/base/envs/py311ray/lib/python3.11/site-packages/ray/tune/trainable/trainable.py", line 330, in train
    raise skipped from exception_cause(skipped)
  File "/opt/homebrew/Caskroom/miniconda/base/envs/py311ray/lib/python3.11/site-packages/ray/air/_internal/util.py", line 107, in run
    self._ret = self._target(*self._args, **self._kwargs)
                ^^^^^^^^^^^^^^^^^^^^^^^^^^^^^^^^^^^^^^^^^
  File "/opt/homebrew/Caskroom/miniconda/base/envs/py311ray/lib/python3.11/site-packages/ray/tune/trainable/function_trainable.py", line 45, in <lambda>
    training_func=lambda: self._trainable_func(self.config),
                          ^^^^^^^^^^^^^^^^^^^^^^^^^^^^^^^^^
           ^^^^^^^^^^^^^^^^^^^^^^^^^^^^^^^
  File "/opt/homebrew/Caskroom/miniconda/base/envs/py311ray/lib/python3.11/site-packages/ray/tune/trainable/function_trainable.py", line 261, in _trainable_func
    output = fn()
             ^^^^
  File "/Users/mikeedwards/Library/Mobile Documents/com~apple~CloudDocs/pMike/Unity/price/run_optuna.py", line 55, in objective
    tune.report(loss=loss)                        # every trial must report!
    ^^^^^^^^^^^^^^^^^^^^^^
  File "/opt/homebrew/Caskroom/miniconda/base/envs/py311ray/lib/python3.11/site-packages/ray/train/_internal/session.py", line 663, in wrapper
    return fn(*args, **kwargs)
           ^^^^^^^^^^^^^^^^^^^
TypeError: report() got an unexpected keyword argument 'loss'
Failure # 4 (occurred at 2025-05-22_20-52-48)
[36mray::ImplicitFunc.train()[39m (pid=59726, ip=127.0.0.1, actor_id=70f75f7ac12fbf0dab429ffc02000000, repr=objective)
           ^^^^^^^^^^^^^^^^^^^^^^^^^^^^^^^^^^^^
           ^^^^^^^^^^^^^^^^^^^^^^^^^^^^^^^
  File "/opt/homebrew/Caskroom/miniconda/base/envs/py311ray/lib/python3.11/site-packages/ray/tune/trainable/trainable.py", line 330, in train
    raise skipped from exception_cause(skipped)
  File "/opt/homebrew/Caskroom/miniconda/base/envs/py311ray/lib/python3.11/site-packages/ray/air/_internal/util.py", line 107, in run
    self._ret = self._target(*self._args, **self._kwargs)
                ^^^^^^^^^^^^^^^^^^^^^^^^^^^^^^^^^^^^^^^^^
  File "/opt/homebrew/Caskroom/miniconda/base/envs/py311ray/lib/python3.11/site-packages/ray/tune/trainable/function_trainable.py", line 45, in <lambda>
    training_func=lambda: self._trainable_func(self.config),
                          ^^^^^^^^^^^^^^^^^^^^^^^^^^^^^^^^^
           ^^^^^^^^^^^^^^^^^^^^^^^^^^^^^^^
  File "/opt/homebrew/Caskroom/miniconda/base/envs/py311ray/lib/python3.11/site-packages/ray/tune/trainable/function_trainable.py", line 261, in _trainable_func
    output = fn()
             ^^^^
  File "/Users/mikeedwards/Library/Mobile Documents/com~apple~CloudDocs/pMike/Unity/price/run_optuna.py", line 55, in objective
    tune.report(loss=loss)                        # every trial must report!
    ^^^^^^^^^^^^^^^^^^^^^^
  File "/opt/homebrew/Caskroom/miniconda/base/envs/py311ray/lib/python3.11/site-packages/ray/train/_internal/session.py", line 663, in wrapper
    return fn(*args, **kwargs)
           ^^^^^^^^^^^^^^^^^^^
TypeError: report() got an unexpected keyword argument 'loss'
