Failure # 1 (occurred at 2025-05-22_21-35-52)
[36mray::ImplicitFunc.train()[39m (pid=74572, ip=127.0.0.1, actor_id=11d03be5493d8862e095828206000000, repr=objective)
  File "/opt/homebrew/Caskroom/miniconda/base/lib/python3.13/site-packages/ray/tune/trainable/trainable.py", line 330, in train
    raise skipped from exception_cause(skipped)
  File "/opt/homebrew/Caskroom/miniconda/base/lib/python3.13/site-packages/ray/air/_internal/util.py", line 107, in run
    self._ret = self._target(*self._args, **self._kwargs)
                ~~~~~~~~~~~~^^^^^^^^^^^^^^^^^^^^^^^^^^^^^
  File "/opt/homebrew/Caskroom/miniconda/base/lib/python3.13/site-packages/ray/tune/trainable/function_trainable.py", line 45, in <lambda>
    training_func=lambda: self._trainable_func(self.config),
                          ~~~~~~~~~~~~~~~~~~~~^^^^^^^^^^^^^
  File "/opt/homebrew/Caskroom/miniconda/base/lib/python3.13/site-packages/ray/tune/trainable/function_trainable.py", line 261, in _trainable_func
    output = fn()
  File "/Users/mikeedwards/Library/Mobile Documents/com~apple~CloudDocs/pMike/Unity/price/run_optuna.py", line 55, in objective
    tune.report(loss=loss, epoch=epoch)
    ~~~~~~~~~~~^^^^^^^^^^^^^^^^^^^^^^^^
  File "/opt/homebrew/Caskroom/miniconda/base/lib/python3.13/site-packages/ray/train/_internal/session.py", line 663, in wrapper
    return fn(*args, **kwargs)
TypeError: report() got an unexpected keyword argument 'loss'
