Failure # 1 (occurred at 2025-05-22_22-11-50)
[36mray::ImplicitFunc.train()[39m (pid=91429, ip=127.0.0.1, actor_id=8ec75699981343b36474b50b01000000, repr=lstm_objective)
           ^^^^^^^^^^^^^^^^^^^^^^^^^^^^^^^^^^^^
           ^^^^^^^^^^^^^^^^^^^^^^^^^^^^^^^
  File "/opt/homebrew/Caskroom/miniconda/base/envs/unity-env/lib/python3.12/site-packages/ray/tune/trainable/trainable.py", line 330, in train
    raise skipped from exception_cause(skipped)
  File "/opt/homebrew/Caskroom/miniconda/base/envs/unity-env/lib/python3.12/site-packages/ray/air/_internal/util.py", line 107, in run
    self._ret = self._target(*self._args, **self._kwargs)
                ^^^^^^^^^^^^^^^^^^^^^^^^^^^^^^^^^^^^^^^^^
  File "/opt/homebrew/Caskroom/miniconda/base/envs/unity-env/lib/python3.12/site-packages/ray/tune/trainable/function_trainable.py", line 45, in <lambda>
    training_func=lambda: self._trainable_func(self.config),
                          ^^^^^^^^^^^^^^^^^^^^^^^^^^^^^^^^^
           ^^^^^^^^^^^^^^^^^^^^^^^^^^^^^^^
  File "/opt/homebrew/Caskroom/miniconda/base/envs/unity-env/lib/python3.12/site-packages/ray/tune/trainable/function_trainable.py", line 261, in _trainable_func
    output = fn()
             ^^^^
  File "/Users/mikeedwards/Library/Mobile Documents/com~apple~CloudDocs/pMike/Unity/price/training/objectives.py", line 24, in lstm_objective
    sample_X, _ = next(iter(train_loader))
                  ^^^^^^^^^^^^^^^^^^^^^^^^
  File "/opt/homebrew/Caskroom/miniconda/base/envs/unity-env/lib/python3.12/site-packages/torch/utils/data/dataloader.py", line 631, in __next__
    data = self._next_data()
           ^^^^^^^^^^^^^^^^^
  File "/opt/homebrew/Caskroom/miniconda/base/envs/unity-env/lib/python3.12/site-packages/torch/utils/data/dataloader.py", line 1346, in _next_data
    return self._process_data(data)
           ^^^^^^^^^^^^^^^^^^^^^^^^
  File "/opt/homebrew/Caskroom/miniconda/base/envs/unity-env/lib/python3.12/site-packages/torch/utils/data/dataloader.py", line 1372, in _process_data
    data.reraise()
  File "/opt/homebrew/Caskroom/miniconda/base/envs/unity-env/lib/python3.12/site-packages/torch/_utils.py", line 722, in reraise
    raise exception
TypeError: Caught TypeError in DataLoader worker process 0.
Original Traceback (most recent call last):
  File "/opt/homebrew/Caskroom/miniconda/base/envs/unity-env/lib/python3.12/site-packages/torch/utils/data/_utils/worker.py", line 308, in _worker_loop
    data = fetcher.fetch(index)
           ^^^^^^^^^^^^^^^^^^^^
  File "/opt/homebrew/Caskroom/miniconda/base/envs/unity-env/lib/python3.12/site-packages/torch/utils/data/_utils/fetch.py", line 51, in fetch
    data = [self.dataset[idx] for idx in possibly_batched_index]
            ~~~~~~~~~~~~^^^^^
  File "/Users/mikeedwards/Library/Mobile Documents/com~apple~CloudDocs/pMike/Unity/price/training/datamodule.py", line 28, in __getitem__
    return torch.tensor(self.X[i], dtype=torch.float32), torch.tensor(self.y[i], dtype=torch.float32)
           ^^^^^^^^^^^^^^^^^^^^^^^^^^^^^^^^^^^^^^^^^^^^
TypeError: can't convert np.ndarray of type numpy.object_. The only supported types are: float64, float32, float16, complex64, complex128, int64, int32, int16, int8, uint8, and bool.
