Failure # 1 (occurred at 2025-05-22_21-24-01)
[36mray::ImplicitFunc.train()[39m (pid=69508, ip=127.0.0.1, actor_id=1371befa1aff8a8697a94d3f02000000, repr=objective)
           ^^^^^^^^^^^^^^^^^^^^^^^^^^^^^^^^^^^^
           ^^^^^^^^^^^^^^^^^^^^^^^^^^^^^^^
  File "/opt/homebrew/Caskroom/miniconda/base/envs/py311ray/lib/python3.11/site-packages/ray/tune/trainable/trainable.py", line 330, in train
    raise skipped from exception_cause(skipped)
  File "/opt/homebrew/Caskroom/miniconda/base/envs/py311ray/lib/python3.11/site-packages/ray/air/_internal/util.py", line 107, in run
    self._ret = self._target(*self._args, **self._kwargs)
                ^^^^^^^^^^^^^^^^^^^^^^^^^^^^^^^^^^^^^^^^^
  File "/opt/homebrew/Caskroom/miniconda/base/envs/py311ray/lib/python3.11/site-packages/ray/tune/trainable/function_trainable.py", line 45, in <lambda>
    training_func=lambda: self._trainable_func(self.config),
                          ^^^^^^^^^^^^^^^^^^^^^^^^^^^^^^^^^
           ^^^^^^^^^^^^^^^^^^^^^^^^^^^^^^^
  File "/opt/homebrew/Caskroom/miniconda/base/envs/py311ray/lib/python3.11/site-packages/ray/tune/trainable/function_trainable.py", line 261, in _trainable_func
    output = fn()
             ^^^^
  File "/Users/mikeedwards/Library/Mobile Documents/com~apple~CloudDocs/pMike/Unity/price/run_optuna.py", line 55, in objective
    tune.report(loss=loss)                        # every trial must report!
    ^^^^^^^^^^^^^^^^^^^^^^
  File "/opt/homebrew/Caskroom/miniconda/base/envs/py311ray/lib/python3.11/site-packages/ray/train/_internal/session.py", line 663, in wrapper
    return fn(*args, **kwargs)
           ^^^^^^^^^^^^^^^^^^^
TypeError: report() got an unexpected keyword argument 'loss'
Failure # 2 (occurred at 2025-05-22_21-24-26)
[36mray::ImplicitFunc.train()[39m (pid=69707, ip=127.0.0.1, actor_id=7a3fb4e8b00556fe433586d602000000, repr=objective)
           ^^^^^^^^^^^^^^^^^^^^^^^^^^^^^^^^^^^^
           ^^^^^^^^^^^^^^^^^^^^^^^^^^^^^^^
  File "/opt/homebrew/Caskroom/miniconda/base/envs/py311ray/lib/python3.11/site-packages/ray/tune/trainable/trainable.py", line 330, in train
    raise skipped from exception_cause(skipped)
  File "/opt/homebrew/Caskroom/miniconda/base/envs/py311ray/lib/python3.11/site-packages/ray/air/_internal/util.py", line 107, in run
    self._ret = self._target(*self._args, **self._kwargs)
                ^^^^^^^^^^^^^^^^^^^^^^^^^^^^^^^^^^^^^^^^^
  File "/opt/homebrew/Caskroom/miniconda/base/envs/py311ray/lib/python3.11/site-packages/ray/tune/trainable/function_trainable.py", line 45, in <lambda>
    training_func=lambda: self._trainable_func(self.config),
                          ^^^^^^^^^^^^^^^^^^^^^^^^^^^^^^^^^
           ^^^^^^^^^^^^^^^^^^^^^^^^^^^^^^^
  File "/opt/homebrew/Caskroom/miniconda/base/envs/py311ray/lib/python3.11/site-packages/ray/tune/trainable/function_trainable.py", line 261, in _trainable_func
    output = fn()
             ^^^^
  File "/Users/mikeedwards/Library/Mobile Documents/com~apple~CloudDocs/pMike/Unity/price/run_optuna.py", line 55, in objective
    tune.report(loss=loss)                        # every trial must report!
    ^^^^^^^^^^^^^^^^^^^^^^
  File "/opt/homebrew/Caskroom/miniconda/base/envs/py311ray/lib/python3.11/site-packages/ray/train/_internal/session.py", line 663, in wrapper
    return fn(*args, **kwargs)
           ^^^^^^^^^^^^^^^^^^^
TypeError: report() got an unexpected keyword argument 'loss'
Failure # 3 (occurred at 2025-05-22_21-25-05)
[36mray::ImplicitFunc.train()[39m (pid=69849, ip=127.0.0.1, actor_id=34ced3b8b7a14bc7aa671afd02000000, repr=objective)
           ^^^^^^^^^^^^^^^^^^^^^^^^^^^^^^^^^^^^
           ^^^^^^^^^^^^^^^^^^^^^^^^^^^^^^^
  File "/opt/homebrew/Caskroom/miniconda/base/envs/py311ray/lib/python3.11/site-packages/ray/tune/trainable/trainable.py", line 330, in train
    raise skipped from exception_cause(skipped)
  File "/opt/homebrew/Caskroom/miniconda/base/envs/py311ray/lib/python3.11/site-packages/ray/air/_internal/util.py", line 107, in run
    self._ret = self._target(*self._args, **self._kwargs)
                ^^^^^^^^^^^^^^^^^^^^^^^^^^^^^^^^^^^^^^^^^
  File "/opt/homebrew/Caskroom/miniconda/base/envs/py311ray/lib/python3.11/site-packages/ray/tune/trainable/function_trainable.py", line 45, in <lambda>
    training_func=lambda: self._trainable_func(self.config),
                          ^^^^^^^^^^^^^^^^^^^^^^^^^^^^^^^^^
           ^^^^^^^^^^^^^^^^^^^^^^^^^^^^^^^
  File "/opt/homebrew/Caskroom/miniconda/base/envs/py311ray/lib/python3.11/site-packages/ray/tune/trainable/function_trainable.py", line 261, in _trainable_func
    output = fn()
             ^^^^
  File "/Users/mikeedwards/Library/Mobile Documents/com~apple~CloudDocs/pMike/Unity/price/run_optuna.py", line 55, in objective
    tune.report(loss=loss)                        # every trial must report!
    ^^^^^^^^^^^^^^^^^^^^^^
  File "/opt/homebrew/Caskroom/miniconda/base/envs/py311ray/lib/python3.11/site-packages/ray/train/_internal/session.py", line 663, in wrapper
    return fn(*args, **kwargs)
           ^^^^^^^^^^^^^^^^^^^
TypeError: report() got an unexpected keyword argument 'loss'
