Failure # 1 (occurred at 2025-05-22_22-18-09)
[36mray::ImplicitFunc.train()[39m (pid=94097, ip=127.0.0.1, actor_id=f03a1275624e5d5c5610049001000000, repr=lstm_objective)
  File "/opt/homebrew/Caskroom/miniconda/base/lib/python3.13/site-packages/ray/tune/trainable/trainable.py", line 330, in train
    raise skipped from exception_cause(skipped)
  File "/opt/homebrew/Caskroom/miniconda/base/lib/python3.13/site-packages/ray/air/_internal/util.py", line 107, in run
    self._ret = self._target(*self._args, **self._kwargs)
                ~~~~~~~~~~~~^^^^^^^^^^^^^^^^^^^^^^^^^^^^^
  File "/opt/homebrew/Caskroom/miniconda/base/lib/python3.13/site-packages/ray/tune/trainable/function_trainable.py", line 45, in <lambda>
    training_func=lambda: self._trainable_func(self.config),
                          ~~~~~~~~~~~~~~~~~~~~^^^^^^^^^^^^^
  File "/opt/homebrew/Caskroom/miniconda/base/lib/python3.13/site-packages/ray/tune/trainable/function_trainable.py", line 261, in _trainable_func
    output = fn()
  File "/Users/mikeedwards/Library/Mobile Documents/com~apple~CloudDocs/pMike/Unity/price/training/objectives.py", line 44, in lstm_objective
    with tune.checkpoint_dir(epoch) as ckpt_dir:
         ^^^^^^^^^^^^^^^^^^^
AttributeError: module 'ray.tune' has no attribute 'checkpoint_dir'
